Workbook

Sheet Population by 5-year age groups
A1: Table Name：Custom_SinglePopulation
A2: Title：Population by 5-year age groups
A3: Update Date：2025.03.12
A4: Download Date：2025.04.24 22:32
A5: Search Year：1970~2070
A6: Source：National Development Council
A7: Population Projections for the R.O.C (Taiwan)
A8: Table URL：https://pop-proj.ndc.gov.tw/main_en/Custom_Detail_Statistics_Search.aspx?n=175&_Query=e483d58e-492b-4d18-bdbb-a7bd46fb777e
D10: 1970 | E10: 1971 | F10: 1972 | G10: 1973 | H10: 1974 | I10: 1975 | J10: 1976 | K10: 1977 | L10: 1978 | M10: 1979 | N10: 1980 | O10: 1981 | P10: 1982 | Q10: 1983 | R10: 1984 | S10: 1985 | T10: 1986 | U10: 1987 | V10: 1988 | W10: 1989 | X10: 1990 | Y10: 1991 | Z10: 1992 | AA10: 1993 | AB10: 1994 | AC10: 1995 | AD10: 1996 | AE10: 1997 | AF10: 1998 | AG10: 1999 | AH10: 2000 | AI10: 2001 | AJ10: 2002 | AK10: 2003 | AL10: 2004 | AM10: 2005 | AN10: 2006 | AO10: 2007 | AP10: 2008 | AQ10: 2009 | AR10: 2010 | AS10: 2011 | AT10: 2012 | AU10: 2013 | AV10: 2014 | AW10: 2015 | AX10: 2016 | AY10: 2017 | AZ10: 2018 | BA10: 2019 | BB10: 2020 | BC10: 2021 | BD10: 2022 | BE10: 2023 | BF10: 2024 | BG10: 2025 | BH10: 2026 | BI10: 2027 | BJ10: 2028 | BK10: 2029 | BL10: 2030 | BM10: 2031 | BN10: 2032 | BO10: 2033 | BP10: 2034 | BQ10: 2035 | BR10: 2036 | BS10: 2037 | BT10: 2038 | BU10: 2039 | BV10: 2040 | BW10: 2041 | BX10: 2042 | BY10: 2043 | BZ10: 2044 | CA10: 2045 | CB10: 2046 | CC10: 2047 | CD10: 2048 | CE10: 2049 | CF10: 2050 | CG10: 2051 | CH10: 2052 | CI10: 2053 | CJ10: 2054 | CK10: 2055 | CL10: 2056 | CM10: 2057 | CN10: 2058 | CO10: 2059 | CP10: 2060 | CQ10: 2061 | CR10: 2062 | CS10: 2063 | CT10: 2064 | CU10: 2065 | CV10: 2066 | CW10: 2067 | CX10: 2068 | CY10: 2069 | CZ10: 2070
A11: Variant | B11: Gender | C11: Age | D11: Data value (persons) | E11: Data value (persons) | F11: Data value (persons) | G11: Data value (persons) | H11: Data value (persons) | I11: Data value (persons) | J11: Data value (persons) | K11: Data value (persons) | L11: Data value (persons) | M11: Data value (persons) | N11: Data value (persons) | O11: Data value (persons) | P11: Data value (persons) | Q11: Data value (persons) | R11: Data value (persons) | S11: Data value (persons) | T11: Data value (persons) | U11: Data value (persons) | V11: Data value (persons) | W11: Data value (persons) | X11: Data value (persons) | Y11: Data value (persons) | Z11: Data value (persons) | AA11: Data value (persons) | AB11: Data value (persons) | AC11: Data value (persons) | AD11: Data value (persons) | AE11: Data value (persons) | AF11: Data value (persons) | AG11: Data value (persons) | AH11: Data value (persons) | AI11: Data value (persons) | AJ11: Data value (persons) | AK11: Data value (persons) | AL11: Data value (persons) | AM11: Data value (persons) | AN11: Data value (persons) | AO11: Data value (persons) | AP11: Data value (persons) | AQ11: Data value (persons) | AR11: Data value (persons) | AS11: Data value (persons) | AT11: Data value (persons) | AU11: Data value (persons) | AV11: Data value (persons) | AW11: Data value (persons) | AX11: Data value (persons) | AY11: Data value (persons) | AZ11: Data value (persons) | BA11: Data value (persons) | BB11: Data value (persons) | BC11: Data value (persons) | BD11: Data value (persons) | BE11: Data value (persons) | BF11: Data value (persons) | BG11: Data value (persons) | BH11: Data value (persons) | BI11: Data value (persons) | BJ11: Data value (persons) | BK11: Data value (persons) | BL11: Data value (persons) | BM11: Data value (persons) | BN11: Data value (persons) | BO11: Data value (persons) | BP11: Data value (persons) | BQ11: Data value (persons) | BR11: Data value (persons) | BS11: Data value (persons) | BT11: Data value (persons) | BU11: Data value (persons) | BV11: Data value (persons) | BW11: Data value (persons) | BX11: Data value (persons) | BY11: Data value (persons) | BZ11: Data value (persons) | CA11: Data value (persons) | CB11: Data value (persons) | CC11: Data value (persons) | CD11: Data value (persons) | CE11: Data value (persons) | CF11: Data value (persons) | CG11: Data value (persons) | CH11: Data value (persons) | CI11: Data value (persons) | CJ11: Data value (persons) | CK11: Data value (persons) | CL11: Data value (persons) | CM11: Data value (persons) | CN11: Data value (persons) | CO11: Data value (persons) | CP11: Data value (persons) | CQ11: Data value (persons) | CR11: Data value (persons) | CS11: Data value (persons) | CT11: Data value (persons) | CU11: Data value (persons) | CV11: Data value (persons) | CW11: Data value (persons) | CX11: Data value (persons) | CY11: Data value (persons) | CZ11: Data value (persons)
A12: Medium | B12: Male | C12: '0-4 | D12: 974034 | E12: 956945 | F12: 955233 | G12: 944241 | H12: 928453 | I12: 923216 | J12: 943386 | K12: 960961 | L12: 986558 | M12: 1014974 | N12: 1031881 | O12: 1028974 | P12: 1035321 | Q12: 1025312 | R12: 995173 | S12: 962831 | T12: 917072 | U12: 869769 | V12: 850875 | W12: 832292 | X12: 836309 | Y12: 843907 | Z12: 848534 | AA12: 838993 | AB12: 836012 | AC12: 828904 | AD12: 828407 | AE12: 831971 | AF12: 804753 | AG12: 784903 | AH12: 776698 | AI12: 743975 | AJ12: 704807 | AK12: 684174 | AL12: 650216 | AM12: 598086 | AN12: 571699 | AO12: 550561 | AP12: 536491 | AQ12: 523013 | AR12: 503400 | AS12: 498746 | AT12: 511559 | AU12: 512213 | AV12: 520880 | AW12: 545209 | AX12: 550649 | AY12: 529720 | AZ12: 522390 | BA12: 505739 | BB12: 479321 | BC12: 448275 | BD12: 420168 | BE12: 401133 | BF12: 381067 | BG12: 365221 | BH12: 351188 | BI12: 345532 | BJ12: 341343 | BK12: 330835 | BL12: 323563 | BM12: 316530 | BN12: 309836 | BO12: 303799 | BP12: 299021 | BQ12: 294684 | BR12: 290620 | BS12: 286942 | BT12: 283862 | BU12: 280850 | BV12: 277558 | BW12: 274021 | BX12: 270530 | BY12: 267059 | BZ12: 263894 | CA12: 261265 | CB12: 259030 | CC12: 256489 | CD12: 253676 | CE12: 250599 | CF12: 247015 | CG12: 242911 | CH12: 238231 | CI12: 233001 | CJ12: 227354 | CK12: 221408 | CL12: 215237 | CM12: 209218 | CN12: 203521 | CO12: 198081 | CP12: 192954 | CQ12: 188206 | CR12: 183902 | CS12: 180006 | CT12: 176478 | CU12: 173310 | CV12: 170467 | CW12: 167888 | CX12: 165481 | CY12: 163248 | CZ12: 161179
A13: Medium | B13: Male | C13: '5-9 | D13: 1032745 | E13: 1031079 | F13: 1021197 | G13: 1007047 | H13: 998334 | I13: 992148 | J13: 980364 | K13: 972833 | L13: 958874 | M13: 946018 | N13: 935627 | O13: 959696 | P13: 974411 | Q13: 999443 | R13: 1028071 | S13: 1048601 | T13: 1041447 | U13: 1045548 | V13: 1032898 | W13: 1007704 | X13: 974530 | Y13: 924557 | Z13: 882271 | AA13: 863197 | AB13: 837095 | AC13: 832631 | AD13: 842803 | AE13: 849722 | AF13: 842641 | AG13: 848731 | AH13: 841773 | AI13: 842623 | AJ13: 843183 | AK13: 812247 | AL13: 791835 | AM13: 783379 | AN13: 749063 | AO13: 709220 | AP13: 689226 | AQ13: 656333 | AR13: 605233 | AS13: 579777 | AT13: 558811 | AU13: 543718 | AV13: 530701 | AW13: 510204 | AX13: 506111 | AY13: 521151 | AZ13: 519411 | BA13: 528204 | BB13: 551328 | BC13: 551480 | BD13: 528980 | BE13: 528263 | BF13: 511337 | BG13: 486230 | BH13: 461276 | BI13: 433013 | BJ13: 408821 | BK13: 389733 | BL13: 373378 | BM13: 358433 | BN13: 352088 | BO13: 347464 | BP13: 337059 | BQ13: 329939 | BR13: 323066 | BS13: 316578 | BT13: 310833 | BU13: 306364 | BV13: 302299 | BW13: 298562 | BX13: 295203 | BY13: 292224 | BZ13: 289292 | CA13: 286081 | CB13: 282679 | CC13: 279307 | CD13: 275980 | CE13: 272894 | CF13: 270346 | CG13: 268208 | CH13: 265815 | CI13: 263081 | CJ13: 259980 | CK13: 256363 | CL13: 252226 | CM13: 247494 | CN13: 242214 | CO13: 236531 | CP13: 230553 | CQ13: 224353 | CR13: 218303 | CS13: 212584 | CT13: 207125 | CU13: 201976 | CV13: 197209 | CW13: 192889 | CX13: 188984 | CY13: 185445 | CZ13: 182262
A14: Medium | B14: Male | C14: '10-14 | D14: 988025 | E14: 999335 | F14: 1025318 | G14: 1035688 | H14: 1039956 | I14: 1035899 | J14: 1035756 | K14: 1016234 | L14: 1004492 | M14: 995791 | N14: 989923 | O14: 975557 | P14: 968414 | Q14: 955552 | R14: 941453 | S14: 931912 | T14: 955801 | U14: 969628 | V14: 993204 | W14: 1019573 | X14: 1038378 | Y14: 1034173 | Z14: 1042014 | AA14: 1026965 | AB14: 1006634 | AC14: 971636 | AD14: 916435 | AE14: 871942 | AF14: 856638 | AG14: 830111 | AH14: 831160 | AI14: 842567 | AJ14: 849202 | AK14: 840744 | AL14: 846780 | AM14: 839692 | AN14: 840418 | AO14: 841204 | AP14: 810883 | AQ14: 790956 | AR14: 782666 | AS14: 748622 | AT14: 709152 | AU14: 689170 | AV14: 656183 | AW14: 605073 | AX14: 579306 | AY14: 558086 | AZ14: 542920 | BA14: 529859 | BB14: 508411 | BC14: 500477 | BD14: 512976 | BE14: 517742 | BF14: 527548 | BG14: 552787 | BH14: 558705 | BI14: 539485 | BJ14: 533110 | BK14: 515486 | BL14: 488910 | BM14: 462917 | BN14: 433721 | BO14: 408714 | BP14: 389769 | BQ14: 373557 | BR14: 358753 | BS14: 352538 | BT14: 348076 | BU14: 337856 | BV14: 330893 | BW14: 324172 | BX14: 317816 | BY14: 312142 | BZ14: 307748 | CA14: 303756 | CB14: 300100 | CC14: 296798 | CD14: 293885 | CE14: 291011 | CF14: 287862 | CG14: 284526 | CH14: 281229 | CI14: 277945 | CJ14: 274872 | CK14: 272338 | CL14: 270212 | CM14: 267830 | CN14: 265109 | CO14: 262021 | CP14: 258423 | CQ14: 254305 | CR14: 249598 | CS14: 244347 | CT14: 238692 | CU14: 232745 | CV14: 226574 | CW14: 220552 | CX14: 214859 | CY14: 209423 | CZ14: 204296
A15: Medium | B15: Male | C15: '15-19 | D15: 899138 | E15: 917597 | F15: 935755 | G15: 954953 | H15: 975768 | I15: 986738 | J15: 998006 | K15: 1018989 | L15: 1030339 | M15: 1033377 | N15: 1028905 | O15: 1026841 | P15: 1009949 | Q15: 997573 | R15: 987739 | S15: 981181 | T15: 966716 | U15: 959733 | V15: 946268 | W15: 931441 | X15: 919522 | Y15: 942699 | Z15: 955702 | AA15: 977797 | AB15: 1011303 | AC15: 1032061 | AD15: 1027808 | AE15: 1034479 | AF15: 1022518 | AG15: 997692 | AH15: 964868 | AI15: 910170 | AJ15: 866630 | AK15: 850160 | AL15: 823881 | AM15: 825590 | AN15: 837559 | AO15: 844751 | AP15: 837112 | AQ15: 843652 | AR15: 836734 | AS15: 837814 | AT15: 839044 | AU15: 809139 | AV15: 789321 | AW15: 781104 | AX15: 747320 | AY15: 707868 | AZ15: 687961 | BA15: 655005 | BB15: 602819 | BC15: 574085 | BD15: 551330 | BE15: 541235 | BF15: 528930 | BG15: 508626 | BH15: 504319 | BI15: 519310 | BJ15: 517979 | BK15: 527837 | BL15: 552984 | BM15: 558825 | BN15: 539380 | BO15: 532451 | BP15: 514944 | BQ15: 488524 | BR15: 462679 | BS15: 433662 | BT15: 408848 | BU15: 390063 | BV15: 373991 | BW15: 359311 | BX15: 353187 | BY15: 348776 | BZ15: 338634 | CA15: 331736 | CB15: 325080 | CC15: 318774 | CD15: 313161 | CE15: 308823 | CF15: 304880 | CG15: 301269 | CH15: 298015 | CI15: 295132 | CJ15: 292275 | CK15: 289143 | CL15: 285819 | CM15: 282535 | CN15: 279265 | CO15: 276207 | CP15: 273683 | CQ15: 271568 | CR15: 269197 | CS15: 266487 | CT15: 263414 | CU15: 259829 | CV15: 255727 | CW15: 251037 | CX15: 245801 | CY15: 240165 | CZ15: 234240
A16: Medium | B16: Male | C16: '20-24 | D16: 613923 | E16: 704867 | F16: 768298 | G16: 818306 | H16: 858343 | I16: 898252 | J16: 918163 | K16: 931476 | L16: 951283 | M16: 971313 | N16: 983464 | O16: 992278 | P16: 1013074 | Q16: 1023488 | R16: 1027912 | S16: 1024483 | T16: 1021437 | U16: 1004717 | V16: 992769 | W16: 983442 | X16: 974754 | Y16: 959307 | Z16: 952881 | AA16: 939178 | AB16: 922677 | AC16: 911104 | AD16: 935259 | AE16: 948608 | AF16: 972277 | AG16: 1002156 | AH16: 1023835 | AI16: 1018859 | AJ16: 1026165 | AK16: 1012438 | AL16: 988195 | AM16: 956187 | AN16: 902971 | AO16: 860639 | AP16: 845169 | AQ16: 819263 | AR16: 821067 | AS16: 832933 | AT16: 840354 | AU16: 833182 | AV16: 839945 | AW16: 833406 | AX16: 834607 | AY16: 835784 | AZ16: 806031 | BA16: 786337 | BB16: 777563 | BC16: 741685 | BD16: 701233 | BE16: 684099 | BF16: 651847 | BG16: 600774 | BH16: 575220 | BI16: 554287 | BJ16: 539252 | BK16: 526448 | BL16: 506226 | BM16: 502384 | BN16: 517683 | BO16: 516716 | BP16: 526603 | BQ16: 551698 | BR16: 557584 | BS16: 538308 | BT16: 531509 | BU16: 514185 | BV16: 487979 | BW16: 462344 | BX16: 433526 | BY16: 408858 | BZ16: 390199 | CA16: 374239 | CB16: 359674 | CC16: 353611 | CD16: 349259 | CE16: 339193 | CF16: 332364 | CG16: 325777 | CH16: 319539 | CI16: 313977 | CJ16: 309665 | CK16: 305743 | CL16: 302155 | CM16: 298922 | CN16: 296059 | CO16: 293223 | CP16: 290111 | CQ16: 286806 | CR16: 283542 | CS16: 280291 | CT16: 277249 | CU16: 274740 | CV16: 272639 | CW16: 270281 | CX16: 267588 | CY16: 264534 | CZ16: 260965
A17: Medium | B17: Male | C17: '25-29 | D17: 476385 | E17: 468074 | F17: 479747 | G17: 503343 | H17: 545077 | I17: 611328 | J17: 696226 | K17: 758535 | L17: 807497 | M17: 848038 | N17: 887073 | O17: 906402 | P17: 921180 | Q17: 938465 | R17: 958965 | S17: 969901 | T17: 978271 | U17: 997449 | V17: 1007453 | W17: 1012566 | X17: 1011861 | Y17: 1006489 | Z17: 990251 | AA17: 978571 | AB17: 967512 | AC17: 962374 | AD17: 946727 | AE17: 940902 | AF17: 928765 | AG17: 915210 | AH17: 905239 | AI17: 930094 | AJ17: 943791 | AK17: 967088 | AL17: 996749 | AM17: 1018399 | AN17: 1014502 | AO17: 1022008 | AP17: 1009260 | AQ17: 985114 | AR17: 953304 | AS17: 899967 | AT17: 857626 | AU17: 842171 | AV17: 816522 | AW17: 818133 | AX17: 829814 | AY17: 836819 | AZ17: 829259 | BA17: 835899 | BB17: 828469 | BC17: 825351 | BD17: 824703 | BE17: 800683 | BF17: 781870 | BG17: 773417 | BH17: 739576 | BI17: 700176 | BJ17: 680014 | BK17: 647442 | BL17: 597141 | BM17: 572172 | BN17: 551744 | BO17: 537161 | BP17: 524474 | BQ17: 504399 | BR17: 500628 | BS17: 515916 | BT17: 515027 | BU17: 524942 | BV17: 549979 | BW17: 555903 | BX17: 536772 | BY17: 530039 | BZ17: 512832 | CA17: 486775 | CB17: 461290 | CC17: 432626 | CD17: 408101 | CE17: 389551 | CF17: 373690 | CG17: 359215 | CH17: 353208 | CI17: 348893 | CJ17: 338877 | CK17: 332088 | CL17: 325535 | CM17: 319331 | CN17: 313801 | CO17: 309516 | CP17: 305622 | CQ17: 302057 | CR17: 298844 | CS17: 296000 | CT17: 293184 | CU17: 290088 | CV17: 286805 | CW17: 283562 | CX17: 280330 | CY17: 277303 | CZ17: 274811
A18: Medium | B18: Male | C18: '30-34 | D18: 464656 | E18: 475625 | F18: 482578 | G18: 489747 | H18: 487697 | I18: 470618 | J18: 460547 | K18: 470710 | L18: 495426 | M18: 538128 | N18: 603824 | O18: 687339 | P18: 750402 | Q18: 796780 | R18: 837342 | S18: 874647 | T18: 891206 | U18: 902960 | V18: 924044 | W18: 942367 | X18: 957301 | Y18: 964915 | Z18: 983486 | AA18: 994422 | AB18: 999784 | AC18: 999400 | AD18: 996496 | AE18: 980473 | AF18: 971092 | AG18: 962506 | AH18: 957030 | AI18: 943317 | AJ18: 936397 | AK18: 921888 | AL18: 907862 | AM18: 897966 | AN18: 923631 | AO18: 937762 | AP18: 961387 | AQ18: 990622 | AR18: 1012113 | AS18: 1007873 | AT18: 1015792 | AU18: 1003345 | AV18: 979985 | AW18: 948459 | AX18: 895355 | AY18: 852994 | AZ18: 837430 | BA18: 811836 | BB18: 812698 | BC18: 819451 | BD18: 823488 | BE18: 823350 | BF18: 831003 | BG18: 823763 | BH18: 824534 | BI18: 825397 | BJ18: 795777 | BK18: 776384 | BL18: 768454 | BM18: 735320 | BN18: 696629 | BO18: 677019 | BP18: 644684 | BQ18: 594708 | BR18: 569929 | BS18: 549673 | BT18: 535240 | BU18: 522685 | BV18: 502775 | BW18: 499083 | BX18: 514361 | BY18: 513527 | BZ18: 523443 | CA18: 548414 | CB18: 554361 | CC18: 535350 | CD18: 528685 | CE18: 511591 | CF18: 485684 | CG18: 460342 | CH18: 431832 | CI18: 407429 | CJ18: 388969 | CK18: 373192 | CL18: 358792 | CM18: 352821 | CN18: 348533 | CO18: 338568 | CP18: 331816 | CQ18: 325301 | CR18: 319133 | CS18: 313636 | CT18: 309378 | CU18: 305508 | CV18: 301964 | CW18: 298771 | CX18: 295946 | CY18: 293150 | CZ18: 290077
A19: Medium | B19: Male | C19: '35-39 | D19: 457330 | E19: 443409 | F19: 442533 | G19: 442733 | H19: 447096 | I19: 457984 | J19: 469617 | K19: 474152 | L19: 481264 | M19: 481806 | N19: 466043 | O19: 455640 | P19: 466562 | Q19: 489502 | R19: 531587 | S19: 594395 | T19: 673229 | U19: 731800 | V19: 781227 | W19: 819835 | X19: 859616 | Y19: 878637 | Z19: 892329 | AA19: 912226 | AB19: 932906 | AC19: 945331 | AD19: 954943 | AE19: 975340 | AF19: 989035 | AG19: 992806 | AH19: 990211 | AI19: 988598 | AJ19: 971469 | AK19: 960123 | AL19: 951254 | AM19: 945670 | AN19: 932908 | AO19: 926562 | AP19: 913095 | AQ19: 899207 | AR19: 889468 | AS19: 914496 | AT19: 928490 | AU19: 952401 | AV19: 982359 | AW19: 1004245 | AX19: 1000692 | AY19: 1009075 | AZ19: 996693 | BA19: 973587 | BB19: 941428 | BC19: 884401 | BD19: 839523 | BE19: 831586 | BF19: 807507 | BG19: 808093 | BH19: 819052 | BI19: 825642 | BJ19: 817878 | BK19: 824648 | BL19: 818428 | BM19: 819944 | BN19: 821374 | BO19: 792474 | BP19: 773341 | BQ19: 765593 | BR19: 732763 | BS19: 694438 | BT19: 675107 | BU19: 643088 | BV19: 593490 | BW19: 568940 | BX19: 548875 | BY19: 534591 | BZ19: 522186 | CA19: 502450 | CB19: 498850 | CC19: 514113 | CD19: 513348 | CE19: 523323 | CF19: 548279 | CG19: 554274 | CH19: 535399 | CI19: 528820 | CJ19: 511831 | CK19: 486047 | CL19: 460823 | CM19: 432438 | CN19: 408146 | CO19: 389764 | CP19: 374053 | CQ19: 359718 | CR19: 353789 | CS19: 349536 | CT19: 339620 | CU19: 332902 | CV19: 326423 | CW19: 320288 | CX19: 314823 | CY19: 310591 | CZ19: 306745
A20: Medium | B20: Male | C20: '40-44 | D20: 510649 | E20: 510466 | F20: 503534 | G20: 485076 | H20: 466316 | I20: 449433 | J20: 435665 | K20: 432694 | L20: 433277 | M20: 438580 | N20: 451844 | O20: 461495 | P20: 466015 | Q20: 471800 | R20: 473507 | S20: 457537 | T20: 449242 | U20: 460504 | V20: 482685 | W20: 522260 | X20: 585909 | Y20: 663796 | Z20: 722576 | AA20: 770835 | AB20: 810417 | AC20: 848300 | AD20: 865339 | AE20: 878916 | AF20: 900056 | AG20: 919603 | AH20: 931580 | AI20: 941127 | AJ20: 960079 | AK20: 971638 | AL20: 975195 | AM20: 972854 | AN20: 972298 | AO20: 956057 | AP20: 945857 | AQ20: 937285 | AR20: 932140 | AS20: 919426 | AT20: 912991 | AU20: 899869 | AV20: 886945 | AW20: 877836 | AX20: 903230 | AY20: 917671 | AZ20: 941853 | BA20: 972012 | BB20: 993290 | BC20: 985293 | BD20: 990550 | BE20: 986636 | BF20: 965271 | BG20: 933851 | BH20: 881544 | BI20: 839666 | BJ20: 824135 | BK20: 798817 | BL20: 800173 | BM20: 811586 | BN20: 818896 | BO20: 812079 | BP20: 818980 | BQ20: 813036 | BR20: 814741 | BS20: 816376 | BT20: 787872 | BU20: 769074 | BV20: 761629 | BW20: 729240 | BX20: 691365 | BY20: 672248 | BZ20: 640562 | CA20: 591448 | CB20: 567187 | CC20: 547374 | CD20: 533295 | CE20: 521064 | CF20: 501513 | CG20: 498046 | CH20: 513391 | CI20: 512723 | CJ20: 522705 | CK20: 547576 | CL20: 553596 | CM20: 534884 | CN20: 528365 | CO20: 511499 | CP20: 485883 | CQ20: 460819 | CR20: 432594 | CS20: 408437 | CT20: 390184 | CU20: 374582 | CV20: 360345 | CW20: 354468 | CX20: 350255 | CY20: 340403 | CZ20: 333735
A21: Medium | B21: Male | C21: '45-49 | D21: 419615 | E21: 437336 | F21: 456454 | G21: 477338 | H21: 491285 | I21: 500064 | J21: 498187 | K21: 487595 | L21: 470864 | M21: 454348 | N21: 438471 | O21: 425094 | P21: 421329 | Q21: 421124 | R21: 427824 | S21: 439276 | T21: 450112 | U21: 457594 | V21: 463632 | W21: 465199 | X21: 450964 | Y21: 443856 | Z21: 451477 | AA21: 471877 | AB21: 508108 | AC21: 568978 | AD21: 646207 | AE21: 705103 | AF21: 753418 | AG21: 791357 | AH21: 829386 | AI21: 846586 | AJ21: 858992 | AK21: 877898 | AL21: 896871 | AM21: 908705 | AN21: 919910 | AO21: 938532 | AP21: 950823 | AQ21: 954649 | AR21: 952466 | AS21: 951201 | AT21: 935207 | AU21: 925294 | AV21: 917741 | AW21: 913117 | AX21: 901383 | AY21: 895576 | AZ21: 882891 | BA21: 870707 | BB21: 861418 | BC21: 882337 | BD21: 893304 | BE21: 925136 | BF21: 956248 | BG21: 977536 | BH21: 974468 | BI21: 983023 | BJ21: 971313 | BK21: 949285 | BL21: 919541 | BM21: 868533 | BN21: 827718 | BO21: 812850 | BP21: 788189 | BQ21: 789840 | BR21: 801315 | BS21: 808755 | BT21: 802323 | BU21: 809374 | BV21: 803777 | BW21: 805705 | BX21: 807557 | BY21: 779546 | BZ21: 761164 | CA21: 754034 | CB21: 722184 | CC21: 684922 | CD21: 666124 | CE21: 634910 | CF21: 586491 | CG21: 562624 | CH21: 543161 | CI21: 529345 | CJ21: 517339 | CK21: 498043 | CL21: 494718 | CM21: 510070 | CN21: 509498 | CO21: 519495 | CP21: 544212 | CQ21: 550254 | CR21: 531802 | CS21: 525387 | CT21: 508724 | CU21: 483378 | CV21: 458578 | CW21: 430624 | CX21: 406696 | CY21: 388644 | CZ21: 373210
A22: Medium | B22: Male | C22: '50-54 | D22: 300538 | E22: 324003 | F22: 345611 | G22: 363693 | H22: 386283 | I22: 406252 | J22: 422911 | K22: 439976 | L22: 459696 | M22: 475219 | N22: 482632 | O22: 480157 | P22: 470978 | Q22: 454264 | R22: 438062 | S22: 422743 | T22: 411299 | U22: 410236 | V22: 410988 | W22: 416487 | X22: 428066 | Y22: 438826 | Z22: 443183 | AA22: 447587 | AB22: 444463 | AC22: 426680 | AD22: 415574 | AE22: 426471 | AF22: 449997 | AG22: 489804 | AH22: 550932 | AI22: 627410 | AJ22: 683753 | AK22: 729037 | AL22: 765796 | AM22: 803078 | AN22: 821251 | AO22: 833832 | AP22: 853304 | AQ22: 872033 | AR22: 883709 | AS22: 893621 | AT22: 912094 | AU22: 923924 | AV22: 927927 | AW22: 926100 | AX22: 924716 | AY22: 909365 | AZ22: 900275 | BA22: 893605 | BB22: 888663 | BC22: 873204 | BD22: 864564 | BE22: 859477 | BF22: 848743 | BG22: 840286 | BH22: 865566 | BI22: 879838 | BJ22: 903364 | BK22: 932727 | BL22: 954395 | BM22: 952118 | BN22: 961174 | BO22: 950462 | BP22: 929239 | BQ22: 900411 | BR22: 850749 | BS22: 811118 | BT22: 796969 | BU22: 773162 | BV22: 775136 | BW22: 786614 | BX22: 794141 | BY22: 788124 | BZ22: 795265 | CA22: 790046 | CB22: 792185 | CC22: 794237 | CD22: 766864 | CE22: 748998 | CF22: 742254 | CG22: 711130 | CH22: 674702 | CI22: 656300 | CJ22: 625719 | CK22: 578273 | CL22: 554934 | CM22: 535935 | CN22: 522462 | CO22: 510759 | CP22: 491815 | CQ22: 488684 | CR22: 504023 | CS22: 503573 | CT22: 513560 | CU22: 538003 | CV22: 544049 | CW22: 525970 | CX22: 519686 | CY22: 503317 | CZ22: 478375
A23: Medium | B23: Male | C23: '55-59 | D23: 244831 | E23: 253209 | F23: 253340 | G23: 259673 | H23: 267406 | I23: 281813 | J23: 304989 | K23: 323997 | L23: 340614 | M23: 360155 | N23: 382148 | O23: 398702 | P23: 415958 | Q23: 435512 | R23: 450737 | S23: 457701 | T23: 454885 | U23: 448336 | V23: 433808 | W23: 417661 | X23: 402381 | Y23: 391291 | Z23: 389203 | AA23: 389157 | AB23: 390779 | AC23: 400396 | AD23: 408932 | AE23: 414295 | AF23: 421175 | AG23: 421673 | AH23: 405574 | AI23: 397003 | AJ23: 407786 | AK23: 429830 | AL23: 468133 | AM23: 527088 | AN23: 602280 | AO23: 657109 | AP23: 701768 | AQ23: 737598 | AR23: 773674 | AS23: 790656 | AT23: 803377 | AU23: 822075 | AV23: 840614 | AW23: 851684 | AX23: 861044 | AY23: 878847 | AZ23: 890359 | BA23: 894467 | BB23: 892095 | BC23: 886769 | BD23: 868925 | BE23: 866736 | BF23: 861080 | BG23: 857239 | BH23: 847236 | BI23: 842594 | BJ23: 831448 | BK23: 820743 | BL23: 813355 | BM23: 838333 | BN23: 852510 | BO23: 875672 | BP23: 904458 | BQ23: 925731 | BR23: 923941 | BS23: 933021 | BT23: 922933 | BU23: 902665 | BV23: 874949 | BW23: 826974 | BX23: 788795 | BY23: 775433 | BZ23: 752615 | CA23: 754886 | CB23: 766269 | CC23: 773811 | CD23: 768257 | CE23: 775434 | CF23: 770630 | CG23: 772961 | CH23: 775207 | CI23: 748653 | CJ23: 731424 | CK23: 725117 | CL23: 694922 | CM23: 659577 | CN23: 641696 | CO23: 611962 | CP23: 565830 | CQ23: 543192 | CR23: 524798 | CS23: 511774 | CT23: 500467 | CU23: 482011 | CV23: 479109 | CW23: 494365 | CX23: 494047 | CY23: 503973 | CZ23: 527989
... A28: Medium | B28: Male | C28: '80-84 | D28: 13883 | E28: 10693 | F28: 11486 | G28: 12164 | H28: 12809 | I28: 13858 | J28: 14983 | K28: 15892 | L28: 17881 | M28: 19285 | N28: 21252 | O28: 23135 | P28: 25413 | Q28: 27141 | R28: 29701 | S28: 32800 | T28: 34638 | U28: 37690 | V28: 39687 | W28: 43202 | X28: 45807 | Y28: 49856 | Z28: 58049 | AA28: 64618 | AB28: 70333 | AC28: 74364 | AD28: 77128 | AE28: 79065 | AF28: 82971 | AG28: 87710 | AH28: 94920 | AI28: 105011 | AJ28: 114146 | AK28: 122381 | AL28: 131554 | AM28: 143274 | AN28: 153915 | AO28: 163045 | AP28: 173879 | AQ28: 182732 | AR28: 188509 | AS28: 189644 | AT28: 187308 | AU28: 182091 | AV28: 176602 | AW28: 171347 | AX28: 167699 | AY28: 168622 | AZ28: 171621 | BA28: 177638 | BB28: 185500 | BC28: 192117 | BD28: 195255 | BE28: 201014 | BF28: 203244 | BG28: 196382 | BH28: 194085 | BI28: 203155 | BJ28: 217761 | BK28: 240662 | BL28: 272742 | BM28: 312863 | BN28: 341822 | BO28: 366118 | BP28: 385847 | BQ28: 406281 | BR28: 417828 | BS28: 426008 | BT28: 437348 | BU28: 449062 | BV28: 457230 | BW28: 464944 | BX28: 476589 | BY28: 485614 | BZ28: 490816 | CA28: 492938 | CB28: 495427 | CC28: 489829 | CD28: 488567 | CE28: 488508 | CF28: 489728 | CG28: 487067 | CH28: 486349 | CI28: 482676 | CJ28: 479413 | CK28: 478393 | CL28: 497738 | CM28: 508737 | CN28: 525415 | CO28: 545243 | CP28: 559795 | CQ28: 562387 | CR28: 569981 | CS28: 565937 | CT28: 556033 | CU28: 540840 | CV28: 512975 | CW28: 492082 | CX28: 487651 | CY28: 476442 | CZ28: 481308
A29: Medium | B29: Male | C29: '85-89 | D29: - | E29: 3925 | F29: 4535 | G29: 4698 | H29: 4959 | I29: 4173 | J29: 4469 | K29: 4816 | L29: 5082 | M29: 5576 | N29: 6289 | O29: 6803 | P29: 7173 | Q29: 8020 | R29: 8963 | S29: 10214 | T29: 10754 | U29: 11965 | V29: 12973 | W29: 14021 | X29: 15456 | Y29: 16909 | Z29: 18389 | AA29: 19452 | AB29: 21409 | AC29: 23301 | AD29: 25113 | AE29: 29977 | AF29: 33535 | AG29: 36476 | AH29: 38710 | AI29: 41096 | AJ29: 42843 | AK29: 45323 | AL29: 48850 | AM29: 53381 | AN29: 60585 | AO29: 65869 | AP29: 70921 | AQ29: 76946 | AR29: 85006 | AS29: 92019 | AT29: 98577 | AU29: 105360 | AV29: 110329 | AW29: 114167 | AX29: 114543 | AY29: 113012 | AZ29: 109888 | BA29: 106901 | BB29: 104537 | BC29: 102595 | BD29: 101502 | BE29: 103398 | BF29: 107645 | BG29: 114827 | BH29: 120778 | BI29: 125059 | BJ29: 129221 | BK29: 130949 | BL29: 126883 | BM29: 125973 | BN29: 133032 | BO29: 143943 | BP29: 160324 | BQ29: 182127 | BR29: 209546 | BS29: 229348 | BT29: 245984 | BU29: 259744 | BV29: 274246 | BW29: 283283 | BX29: 289562 | BY29: 298217 | BZ29: 307243 | CA29: 314072 | CB29: 320622 | CC29: 329608 | CD29: 336987 | CE29: 341703 | CF29: 344202 | CG29: 347083 | CH29: 344044 | CI29: 344542 | CJ29: 345867 | CK29: 347993 | CL29: 347303 | CM29: 347494 | CN29: 345971 | CO29: 344847 | CP29: 345496 | CQ29: 361541 | CR29: 370532 | CS29: 383836 | CT29: 399350 | CU29: 410637 | CV29: 414078 | CW29: 420449 | CX29: 418276 | CY29: 411979 | CZ29: 401434
A30: Medium | B30: Male | C30: '90-94 | D30: - | E30: - | F30: - | G30: - | H30: - | I30: 1034 | J30: 1027 | K30: 1116 | L30: 1194 | M30: 1311 | N30: 1427 | O30: 1517 | P30: 1729 | Q30: 1867 | R30: 2052 | S30: 2325 | T30: 2420 | U30: 2681 | V30: 3046 | W30: 3292 | X30: 3521 | Y30: 4158 | Z30: 4186 | AA30: 4619 | AB30: 5198 | AC30: 5738 | AD30: 6278 | AE30: 6951 | AF30: 7485 | AG30: 8311 | AH30: 9168 | AI30: 10045 | AJ30: 12364 | AK30: 14162 | AL30: 15551 | AM30: 16760 | AN30: 18114 | AO30: 18087 | AP30: 19429 | AQ30: 21348 | AR30: 23822 | AS30: 26964 | AT30: 30022 | AU30: 32648 | AV30: 35264 | AW30: 39070 | AX30: 42154 | AY30: 44987 | AZ30: 48077 | BA30: 50353 | BB30: 52093 | BC30: 52177 | BD30: 49654 | BE30: 47217 | BF30: 45718 | BG30: 47131 | BH30: 47551 | BI30: 48982 | BJ30: 51064 | BK30: 54088 | BL30: 57441 | BM30: 60697 | BN30: 63036 | BO30: 65346 | BP30: 66436 | BQ30: 64372 | BR30: 64302 | BS30: 68810 | BT30: 75478 | BU30: 84980 | BV30: 96786 | BW30: 111787 | BX30: 122542 | BY30: 131556 | BZ30: 139180 | CA30: 147453 | CB30: 153259 | CC30: 157210 | CD30: 162745 | CE30: 168678 | CF30: 173695 | CG30: 178617 | CH30: 184696 | CI30: 190058 | CJ30: 193949 | CK30: 196460 | CL30: 199259 | CM30: 198402 | CN30: 200016 | CO30: 202069 | CP30: 204477 | CQ30: 205137 | CR30: 205888 | CS30: 205962 | CT30: 206366 | CU30: 207959 | CV30: 219443 | CW30: 225709 | CX30: 234871 | CY30: 245361 | CZ30: 252888
A31: Medium | B31: Male | C31: '95-99 | D31: - | E31: - | F31: - | G31: - | H31: - | I31: - | J31: - | K31: - | L31: - | M31: - | N31: - | O31: - | P31: - | Q31: - | R31: - | S31: - | T31: - | U31: - | V31: - | W31: - | X31: - | Y31: - | Z31: 606 | AA31: 680 | AB31: 808 | AC31: 905 | AD31: 1078 | AE31: 1271 | AF31: 1423 | AG31: 1611 | AH31: 1807 | AI31: 1994 | AJ31: 2213 | AK31: 2421 | AL31: 2713 | AM31: 2944 | AN31: 3293 | AO31: 4120 | AP31: 4435 | AQ31: 4825 | AR31: 5201 | AS31: 5524 | AT31: 5752 | AU31: 6225 | AV31: 6771 | AW31: 7552 | AX31: 8597 | AY31: 9585 | AZ31: 10265 | BA31: 10985 | BB31: 12345 | BC31: 13336 | BD31: 13356 | BE31: 13627 | BF31: 13903 | BG31: 15094 | BH31: 15344 | BI31: 15305 | BJ31: 15076 | BK31: 15002 | BL31: 15165 | BM31: 15479 | BN31: 16117 | BO31: 16937 | BP31: 18094 | BQ31: 19366 | BR31: 20562 | BS31: 21404 | BT31: 22261 | BU31: 22703 | BV31: 21942 | BW31: 22103 | BX31: 24123 | BY31: 26938 | BZ31: 30718 | CA31: 35053 | CB31: 40724 | CC31: 44750 | CD31: 48217 | CE31: 51394 | CF31: 55113 | CG31: 58183 | CH31: 60380 | CI31: 63387 | CJ31: 66773 | CK31: 69859 | CL31: 72885 | CM31: 76243 | CN31: 79361 | CO31: 81764 | CP31: 83518 | CQ31: 85443 | CR31: 85610 | CS31: 87115 | CT31: 88769 | CU31: 90509 | CV31: 91340 | CW31: 91962 | CX31: 92619 | CY31: 93556 | CZ31: 95032
A32: Medium | B32: Male | C32: '100 + | D32: - | E32: - | F32: - | G32: - | H32: - | I32: - | J32: - | K32: - | L32: - | M32: - | N32: - | O32: - | P32: - | Q32: - | R32: - | S32: - | T32: - | U32: - | V32: - | W32: - | X32: - | Y32: - | Z32: 79 | AA32: 122 | AB32: 164 | AC32: 175 | AD32: 203 | AE32: 275 | AF32: 319 | AG32: 348 | AH32: 388 | AI32: 477 | AJ32: 606 | AK32: 682 | AL32: 786 | AM32: 884 | AN32: 1005 | AO32: 1005 | AP32: 931 | AQ32: 977 | AR32: 1036 | AS32: 1027 | AT32: 1315 | AU32: 1418 | AV32: 1452 | AW32: 1442 | AX32: 1404 | AY32: 1521 | AZ32: 1568 | BA32: 1687 | BB32: 1877 | BC32: 2099 | BD32: 2197 | BE32: 2148 | BF32: 2207 | BG32: 2089 | BH32: 2201 | BI32: 2290 | BJ32: 2397 | BK32: 2479 | BL32: 2587 | BM32: 2635 | BN32: 2629 | BO32: 2605 | BP32: 2627 | BQ32: 2707 | BR32: 2800 | BS32: 2943 | BT32: 3109 | BU32: 3348 | BV32: 3609 | BW32: 3841 | BX32: 4002 | BY32: 4186 | BZ32: 4296 | CA32: 4146 | CB32: 4270 | CC32: 4829 | CD32: 5536 | CE32: 6428 | CF32: 7377 | CG32: 8741 | CH32: 9765 | CI32: 10734 | CJ32: 11775 | CK32: 13034 | CL32: 14238 | CM32: 15107 | CN32: 16261 | CO32: 17501 | CP32: 18704 | CQ32: 19871 | CR32: 21039 | CS32: 22215 | CT32: 23187 | CU32: 23964 | CV32: 24812 | CW32: 25090 | CX32: 25976 | CY32: 26875 | CZ32: 27682
A33: Medium | B33: Female | C33: '0-4 | D33: 914496 | E33: 897739 | F33: 897494 | G33: 887969 | H33: 873886 | I33: 869235 | J33: 887840 | K33: 902486 | L33: 924598 | M33: 950828 | N33: 965542 | O33: 964024 | P33: 970605 | Q33: 963365 | R33: 934241 | S33: 903718 | T33: 860449 | U33: 814610 | V33: 793019 | W33: 774313 | X33: 776979 | Y33: 779539 | Z33: 781019 | AA33: 775605 | AB33: 765620 | AC33: 761581 | AD33: 762568 | AE33: 767123 | AF33: 741136 | AG33: 722318 | AH33: 712544 | AI33: 682784 | AJ33: 646022 | AK33: 625729 | AL33: 593723 | AM33: 546269 | AN33: 521243 | AO33: 502024 | AP33: 489715 | AQ33: 479147 | AR33: 460693 | AS33: 458244 | AT33: 472124 | AU33: 474738 | AV33: 484246 | AW33: 507246 | AX33: 512414 | AY33: 492679 | AZ33: 486589 | BA33: 470062 | BB33: 445981 | BC33: 417465 | BD33: 391565 | BE33: 373923 | BF33: 355460 | BG33: 340197 | BH33: 326302 | BI33: 320686 | BJ33: 316579 | BK33: 307178 | BL33: 300636 | BM33: 294171 | BN33: 287867 | BO33: 282054 | BP33: 277266 | BQ33: 272797 | BR33: 268584 | BS33: 264558 | BT33: 260759 | BU33: 257089 | BV33: 253321 | BW33: 249502 | BX33: 245861 | BY33: 242383 | BZ33: 239069 | CA33: 236271 | CB33: 233909 | CC33: 231383 | CD33: 228506 | CE33: 225284 | CF33: 221615 | CG33: 217495 | CH33: 212910 | CI33: 207945 | CJ33: 202679 | CK33: 197133 | CL33: 191375 | CM33: 185758 | CN33: 180440 | CO33: 175364 | CP33: 170578 | CQ33: 166146 | CR33: 162129 | CS33: 158499 | CT33: 155209 | CU33: 152251 | CV33: 149600 | CW33: 147193 | CX33: 144947 | CY33: 142862 | CZ33: 140934
A34: Medium | B34: Female | C34: '5-9 | D34: 974686 | E34: 973382 | F34: 964347 | G34: 950864 | H34: 943482 | I34: 935779 | J34: 925158 | K34: 919894 | L34: 904222 | M34: 892214 | N34: 882684 | O34: 905243 | P34: 919905 | Q34: 942793 | R34: 968824 | S34: 987352 | T34: 980525 | U34: 984054 | V34: 971695 | W34: 947898 | X34: 918758 | Y34: 869452 | Z34: 826454 | AA34: 806601 | AB34: 778439 | AC34: 768728 | AD34: 772574 | AE34: 777293 | AF34: 771031 | AG34: 776547 | AH34: 773385 | AI34: 776341 | AJ34: 778195 | AK34: 748799 | AL34: 729180 | AM34: 719557 | AN34: 688097 | AO34: 650560 | AP34: 630644 | AQ34: 599594 | AR34: 553071 | AS34: 528609 | AT34: 509463 | AU34: 496255 | AV34: 486111 | AW34: 467314 | AX34: 465155 | AY34: 481281 | AZ34: 481169 | BA34: 491118 | BB34: 512858 | BC34: 512941 | BD34: 492051 | BE34: 492373 | BF34: 476003 | BG34: 452886 | BH34: 430317 | BI34: 404161 | BJ34: 381260 | BK34: 363104 | BL34: 347790 | BM34: 333019 | BN34: 326725 | BO34: 322131 | BP34: 312675 | BQ34: 306097 | BR34: 299596 | BS34: 293266 | BT34: 287414 | BU34: 282586 | BV34: 278074 | BW34: 273809 | BX34: 269737 | BY34: 265914 | BZ34: 262224 | CA34: 258415 | CB34: 254586 | CC34: 250983 | CD34: 247562 | CE34: 244331 | CF34: 241626 | CG34: 239346 | CH34: 236875 | CI34: 234052 | CJ34: 230896 | CK34: 227291 | CL34: 223230 | CM34: 218681 | CN34: 213752 | CO34: 208528 | CP34: 203016 | CQ34: 197286 | CR34: 191692 | CS34: 186399 | CT34: 181349 | CU34: 176588 | CV34: 172181 | CW34: 168191 | CX34: 164592 | CY34: 161331 | CZ34: 158403
A35: Medium | B35: Female | C35: '10-14 | D35: 937153 | E35: 946702 | F35: 969811 | G35: 979147 | H35: 983279 | I35: 981344 | J35: 981982 | K35: 962877 | L35: 948601 | M35: 940884 | N35: 933591 | O35: 920863 | P35: 916700 | Q35: 903449 | R35: 890555 | S35: 881730 | T35: 903372 | U35: 916989 | V35: 937181 | W35: 961417 | X35: 980411 | Y35: 975522 | Z35: 981055 | AA35: 968344 | AB35: 945781 | AC35: 912603 | AD35: 859756 | AE35: 816229 | AF35: 799201 | AG35: 771986 | AH35: 767533 | AI35: 773594 | AJ35: 777483 | AK35: 769927 | AL35: 775348 | AM35: 772066 | AN35: 775111 | AO35: 777076 | AP35: 748244 | AQ35: 728975 | AR35: 719248 | AS35: 687792 | AT35: 650568 | AU35: 630507 | AV35: 599179 | AW35: 552734 | AX35: 528246 | AY35: 508956 | AZ35: 495748 | BA35: 485369 | BB35: 465497 | BC35: 459270 | BD35: 473429 | BE35: 479979 | BF35: 490971 | BG35: 515027 | BH35: 520928 | BI35: 502883 | BJ35: 497723 | BK35: 480377 | BL35: 455778 | BM35: 432065 | BN35: 404839 | BO35: 381012 | BP35: 362937 | BQ35: 347693 | BR35: 332989 | BS35: 326719 | BT35: 322145 | BU35: 312722 | BV35: 306171 | BW35: 299699 | BX35: 293391 | BY35: 287565 | BZ35: 282757 | CA35: 278264 | CB35: 274041 | CC35: 270037 | CD35: 266305 | CE35: 262733 | CF35: 259069 | CG35: 255378 | CH35: 251908 | CI35: 248619 | CJ35: 245519 | CK35: 242940 | CL35: 240782 | CM35: 238431 | CN35: 235729 | CO35: 232689 | CP35: 229198 | CQ35: 225248 | CR35: 220806 | CS35: 215977 | CT35: 210844 | CU35: 205417 | CV35: 199765 | CW35: 194243 | CX35: 189020 | CY35: 184035 | CZ35: 179334
A36: Medium | B36: Female | C36: '15-19 | D36: 854662 | E36: 873685 | F36: 891942 | G36: 909300 | H36: 930499 | I36: 940249 | J36: 949794 | K36: 967489 | L36: 978231 | M36: 980448 | N36: 978227 | O36: 976914 | P36: 959145 | Q36: 945746 | R36: 938387 | S36: 931079 | T36: 915827 | U36: 912675 | V36: 900225 | W36: 887211 | X36: 876950 | Y36: 897348 | Z36: 908876 | AA36: 928393 | AB36: 957320 | AC36: 976274 | AD36: 971801 | AE36: 977774 | AF36: 966760 | AG36: 942560 | AH36: 910495 | AI36: 858177 | AJ36: 814496 | AK36: 795888 | AL36: 768784 | AM36: 764664 | AN36: 771109 | AO36: 775575 | AP36: 768840 | AQ36: 774675 | AR36: 771420 | AS36: 774423 | AT36: 776481 | AU36: 747813 | AV36: 728480 | AW36: 718731 | AX36: 687456 | AY36: 650204 | AZ36: 630304 | BA36: 599136 | BB36: 551607 | BC36: 523649 | BD36: 503071 | BE36: 495262 | BF36: 485827 | BG36: 466879 | BH36: 464321 | BI36: 480413 | BJ36: 480811 | BK36: 491975 | BL36: 516127 | BM36: 521942 | BN36: 503601 | BO36: 497750 | BP36: 480449 | BQ36: 455918 | BR36: 432262 | BS36: 405110 | BT36: 381334 | BU36: 363300 | BV36: 348091 | BW36: 333416 | BX36: 327157 | BY36: 322595 | BZ36: 313197 | CA36: 306662 | CB36: 300198 | CC36: 293899 | CD36: 288079 | CE36: 283284 | CF36: 278821 | CG36: 274626 | CH36: 270645 | CI36: 266941 | CJ36: 263398 | CK36: 259763 | CL36: 256100 | CM36: 252655 | CN36: 249392 | CO36: 246317 | CP36: 243760 | CQ36: 241625 | CR36: 239295 | CS36: 236615 | CT36: 233594 | CU36: 230126 | CV36: 226198 | CW36: 221777 | CX36: 216966 | CY36: 211852 | CZ36: 206444
A37: Medium | B37: Female | C37: '20-24 | D37: 584014 | E37: 668099 | F37: 731832 | G37: 778889 | H37: 819801 | I37: 858571 | J37: 876596 | K37: 889171 | L37: 908037 | M37: 928167 | N37: 938374 | O37: 947389 | P37: 966477 | Q37: 974687 | R37: 978274 | S37: 975088 | T37: 972885 | U37: 956137 | V37: 944902 | W37: 935318 | X37: 927382 | Y37: 912295 | Z37: 906796 | AA37: 892492 | AB37: 878044 | AC37: 868467 | AD37: 889555 | AE37: 902965 | AF37: 927993 | AG37: 956601 | AH37: 977952 | AI37: 973513 | AJ37: 978706 | AK37: 964793 | AL37: 939894 | AM37: 908333 | AN37: 857516 | AO37: 814957 | AP37: 797136 | AQ37: 770663 | AR37: 765670 | AS37: 771069 | AT37: 775225 | AU37: 768360 | AV37: 773938 | AW37: 770557 | AX37: 773542 | AY37: 775760 | AZ37: 747078 | BA37: 727768 | BB37: 717320 | BC37: 683039 | BD37: 644631 | BE37: 628736 | BF37: 598473 | BG37: 552109 | BH37: 527405 | BI37: 507843 | BJ37: 494415 | BK37: 484142 | BL37: 465363 | BM37: 463368 | BN37: 479976 | BO37: 480867 | BP37: 492012 | BQ37: 516068 | BR37: 521854 | BS37: 503580 | BT37: 497726 | BU37: 480469 | BV37: 456008 | BW37: 432425 | BX37: 405352 | BY37: 381650 | BZ37: 363675 | CA37: 348511 | CB37: 333879 | CC37: 327626 | CD37: 323055 | CE37: 313658 | CF37: 307107 | CG37: 300627 | CH37: 294317 | CI37: 288487 | CJ37: 283680 | CK37: 279204 | CL37: 274997 | CM37: 271008 | CN37: 267289 | CO37: 263731 | CP37: 260087 | CQ37: 256414 | CR37: 252959 | CS37: 249683 | CT37: 246597 | CU37: 244026 | CV37: 241877 | CW37: 239534 | CX37: 236843 | CY37: 233815 | CZ37: 230342
A38: Medium | B38: Female | C38: '25-29 | D38: 449632 | E38: 440686 | F38: 454210 | G38: 475346 | H38: 516386 | I38: 579845 | J38: 662162 | K38: 722374 | L38: 770077 | M38: 810167 | N38: 847952 | O38: 866486 | P38: 882902 | Q38: 899467 | R38: 919540 | S38: 928135 | T38: 935544 | U38: 950823 | V38: 962210 | W38: 962794 | X38: 962696 | Y38: 959244 | Z38: 943708 | AA38: 932646 | AB38: 924775 | AC38: 918641 | AD38: 904388 | AE38: 901768 | AF38: 892062 | AG38: 880849 | AH38: 873639 | AI38: 898649 | AJ38: 912380 | AK38: 934343 | AL38: 961852 | AM38: 984102 | AN38: 984295 | AO38: 995008 | AP38: 985307 | AQ38: 965727 | AR38: 933395 | AS38: 878871 | AT38: 830809 | AU38: 808320 | AV38: 776715 | AW38: 768294 | AX38: 772223 | AY38: 775391 | AZ38: 768132 | BA38: 773555 | BB38: 769144 | BC38: 765891 | BD38: 767224 | BE38: 746104 | BF38: 728093 | BG38: 718725 | BH38: 686297 | BI38: 647860 | BJ38: 627254 | BK38: 596845 | BL38: 551302 | BM38: 527530 | BN38: 508799 | BO38: 495950 | BP38: 485728 | BQ38: 467030 | BR38: 465046 | BS38: 481570 | BT38: 482415 | BU38: 493471 | BV38: 517350 | BW38: 523082 | BX38: 504905 | BY38: 499055 | BZ38: 481878 | CA38: 457545 | CB38: 434091 | CC38: 407158 | CD38: 383568 | CE38: 365679 | CF38: 350579 | CG38: 336015 | CH38: 329780 | CI38: 325218 | CJ38: 315864 | CK38: 309339 | CL38: 302890 | CM38: 296604 | CN38: 290801 | CO38: 286015 | CP38: 281555 | CQ38: 277361 | CR38: 273388 | CS38: 269686 | CT38: 266141 | CU38: 262509 | CV38: 258848 | CW38: 255405 | CX38: 252140 | CY38: 249067 | CZ38: 246503
A39: Medium | B39: Female | C39: '30-34 | D39: 443492 | E39: 454091 | F39: 461108 | G39: 465211 | H39: 463417 | I39: 445929 | J39: 436099 | K39: 445544 | L39: 468886 | M39: 508883 | N39: 570999 | O39: 653342 | P39: 713970 | Q39: 762193 | R39: 802560 | S39: 838408 | T39: 854409 | U39: 865494 | V39: 885792 | W39: 903770 | X39: 914217 | Y39: 924204 | Z39: 941089 | AA39: 951036 | AB39: 959865 | AC39: 958977 | AD39: 957824 | AE39: 942065 | AF39: 933424 | AG39: 927158 | AH39: 923495 | AI39: 912193 | AJ39: 910956 | AK39: 899141 | AL39: 889075 | AM39: 883579 | AN39: 912357 | AO39: 929007 | AP39: 955283 | AQ39: 991472 | AR39: 1016997 | AS39: 1015193 | AT39: 1023196 | AU39: 1010845 | AV39: 985507 | AW39: 949465 | AX39: 892212 | AY39: 840441 | AZ39: 815508 | BA39: 782296 | BB39: 771245 | BC39: 766264 | BD39: 766445 | BE39: 768994 | BF39: 775514 | BG39: 774363 | BH39: 776066 | BI39: 776680 | BJ39: 747043 | BK39: 728532 | BL39: 719357 | BM39: 688886 | BN39: 652455 | BO39: 633074 | BP39: 602841 | BQ39: 557552 | BR39: 533899 | BS39: 515236 | BT39: 502387 | BU39: 492152 | BV39: 473518 | BW39: 471498 | BX39: 487871 | BY39: 488692 | BZ39: 499647 | CA39: 523360 | CB39: 529029 | CC39: 510938 | CD39: 505094 | CE39: 487979 | CF39: 463753 | CG39: 440405 | CH39: 413605 | CI39: 390141 | CJ39: 372354 | CK39: 357338 | CL39: 342855 | CM39: 336652 | CN39: 332107 | CO39: 322804 | CP39: 316313 | CQ39: 309896 | CR39: 303641 | CS39: 297866 | CT39: 293101 | CU39: 288662 | CV39: 284490 | CW39: 280536 | CX39: 276846 | CY39: 273314 | CZ39: 269700
A40: Medium | B40: Female | C40: '35-39 | D40: 388501 | E40: 394998 | F40: 408148 | G40: 417270 | H40: 427986 | I40: 438834 | J40: 450182 | K40: 454086 | L40: 459284 | M40: 457170 | N40: 441155 | O40: 430926 | P40: 441769 | Q40: 464485 | R40: 505110 | S40: 565057 | T40: 641140 | U40: 699184 | V40: 748823 | W40: 786760 | X40: 825028 | Y40: 841932 | Z40: 857434 | AA40: 876875 | AB40: 901674 | AC40: 913049 | AD40: 922264 | AE40: 940571 | AF40: 954832 | AG40: 958278 | AH40: 958242 | AI40: 958222 | AJ40: 942289 | AK40: 931722 | AL40: 926468 | AM40: 924556 | AN40: 917352 | AO40: 918842 | AP40: 910492 | AQ40: 905787 | AR40: 902236 | AS40: 930095 | AT40: 945898 | AU40: 971681 | AV40: 1001868 | AW40: 1024829 | AX40: 1022480 | AY40: 1030464 | AZ40: 1017209 | BA40: 991358 | BB40: 952846 | BC40: 886781 | BD40: 832960 | BE40: 817380 | BF40: 785530 | BG40: 777306 | BH40: 778965 | BI40: 779910 | BJ40: 771482 | BK40: 777112 | BL40: 774249 | BM40: 777780 | BN40: 780687 | BO40: 752992 | BP40: 734575 | BQ40: 725433 | BR40: 695130 | BS40: 658887 | BT40: 639554 | BU40: 609437 | BV40: 564366 | BW40: 540801 | BX40: 522209 | BY40: 509426 | BZ40: 499236 | CA40: 480691 | CB40: 478654 | CC40: 494906 | CD40: 495691 | CE40: 506546 | CF40: 530066 | CG40: 535655 | CH40: 517630 | CI40: 511788 | CJ40: 494761 | CK40: 470670 | CL40: 447453 | CM40: 420807 | CN40: 397480 | CO40: 379790 | CP40: 364859 | CQ40: 350459 | CR40: 344285 | CS40: 339758 | CT40: 330503 | CU40: 324041 | CV40: 317655 | CW40: 311430 | CX40: 305686 | CY40: 300945 | CZ40: 296525
A41: Medium | B41: Female | C41: '40-44 | D41: 339713 | E41: 349640 | F41: 360427 | G41: 367640 | H41: 375151 | I41: 384788 | J41: 391303 | K41: 401383 | L41: 411227 | M41: 422104 | N41: 434682 | O41: 445109 | P41: 449318 | Q41: 454355 | R41: 452870 | S41: 437145 | T41: 429068 | U41: 441298 | V41: 462406 | W41: 500053 | X41: 559328 | Y41: 635554 | Z41: 692766 | AA41: 741550 | AB41: 784055 | AC41: 821938 | AD41: 838760 | AE41: 853954 | AF41: 875959 | AG41: 896277 | AH41: 908597 | AI41: 918228 | AJ41: 935973 | AK41: 947625 | AL41: 951241 | AM41: 952202 | AN41: 955249 | AO41: 940956 | AP41: 932657 | AQ41: 930830 | AR41: 930305 | AS41: 922634 | AT41: 924215 | AU41: 915802 | AV41: 907713 | AW41: 903196 | AX41: 930523 | AY41: 946420 | AZ41: 972195 | BA41: 1002276 | BB41: 1023319 | BC41: 1012869 | BD41: 1019133 | BE41: 1015940 | BF41: 991692 | BG41: 955077 | BH41: 895953 | BI41: 842856 | BJ41: 816446 | BK41: 783456 | BL41: 774461 | BM41: 777570 | BN41: 780431 | BO41: 773517 | BP41: 779117 | BQ41: 776277 | BR41: 779787 | BS41: 782668 | BT41: 755127 | BU41: 736799 | BV41: 727697 | BW41: 697564 | BX41: 661534 | BY41: 642327 | BZ41: 612401 | CA41: 567612 | CB41: 544181 | CC41: 525683 | CD41: 512946 | CE41: 502776 | CF41: 484296 | CG41: 482221 | CH41: 498322 | CI41: 499060 | CJ41: 509814 | CK41: 533145 | CL41: 538661 | CM41: 520721 | CN41: 514880 | CO41: 497935 | CP41: 473980 | CQ41: 450894 | CR41: 424407 | CS41: 401216 | CT41: 383631 | CU41: 368784 | CV41: 354464 | CW41: 348309 | CX41: 343791 | CY41: 334582 | CZ41: 328148
A42: Medium | B42: Female | C42: '45-49 | D42: 278713 | E42: 287346 | F42: 297826 | G42: 311736 | H42: 323181 | I42: 334972 | J42: 345113 | K42: 353295 | L42: 359897 | M42: 368784 | N42: 379402 | O42: 385138 | P42: 396118 | Q42: 404731 | R42: 416335 | S42: 429071 | T42: 439605 | U42: 446263 | V42: 450678 | W42: 450301 | X42: 436578 | Y42: 429411 | Z42: 435910 | AA42: 456068 | AB42: 492635 | AC42: 551629 | AD42: 629281 | AE42: 687336 | AF42: 736966 | AG42: 776424 | AH42: 815063 | AI42: 832299 | AJ42: 847162 | AK42: 866629 | AL42: 886843 | AM42: 900035 | AN42: 912538 | AO42: 931153 | AP42: 945023 | AQ42: 950826 | AR42: 952402 | AS42: 954537 | AT42: 939746 | AU42: 931020 | AV42: 927363 | AW42: 926007 | AX42: 918614 | AY42: 920566 | AZ42: 912359 | BA42: 904621 | BB42: 898799 | BC42: 919349 | BD42: 934008 | BE42: 967449 | BF42: 998655 | BG42: 1021281 | BH42: 1017766 | BI42: 1024625 | BJ42: 1010593 | BK42: 984542 | BL42: 948370 | BM42: 890934 | BN42: 839666 | BO42: 814648 | BP42: 781944 | BQ42: 773062 | BR42: 776176 | BS42: 779042 | BT42: 772197 | BU42: 777773 | BV42: 774978 | BW42: 778484 | BX42: 781365 | BY42: 754037 | BZ42: 735868 | CA42: 726861 | CB42: 696938 | CC42: 661153 | CD42: 642050 | CE42: 612288 | CF42: 567762 | CG42: 544448 | CH42: 526036 | CI42: 513354 | CJ42: 503231 | CK42: 484856 | CL42: 482772 | CM42: 498735 | CN42: 499441 | CO42: 510096 | CP42: 533233 | CQ42: 538681 | CR42: 520843 | CS42: 515020 | CT42: 498169 | CU42: 474362 | CV42: 451420 | CW42: 425107 | CX42: 402065 | CY42: 384590 | CZ42: 369832
A43: Medium | B43: Female | C43: '50-54 | D43: 213902 | E43: 228075 | F43: 240321 | G43: 250487 | H43: 260992 | I43: 271937 | J43: 281341 | K43: 289342 | L43: 303303 | M43: 315662 | N43: 328450 | O43: 338098 | P43: 346037 | Q43: 352867 | R43: 362162 | S43: 372571 | T43: 378909 | U43: 391966 | V43: 401159 | W43: 411001 | X43: 423910 | Y43: 434824 | Z43: 438999 | AA43: 443576 | AB43: 439224 | AC43: 421684 | AD43: 411471 | AE43: 422080 | AF43: 445194 | AG43: 484739 | AH43: 545257 | AI43: 623115 | AJ43: 679977 | AK43: 727398 | AL43: 766611 | AM43: 805313 | AN43: 825295 | AO43: 841159 | AP43: 862593 | AQ43: 883697 | AR43: 896683 | AS43: 907285 | AT43: 926068 | AU43: 939840 | AV43: 944225 | AW43: 945217 | AX43: 946932 | AY43: 932286 | AZ43: 923919 | BA43: 920541 | BB43: 917980 | BC43: 904568 | BD43: 905619 | BE43: 904583 | BF43: 897970 | BG43: 893635 | BH43: 920085 | BI43: 934948 | BJ43: 959491 | BK43: 989119 | BL43: 1011795 | BM43: 1009295 | BN43: 1017218 | BO43: 1004302 | BP43: 978568 | BQ43: 942787 | BR43: 885913 | BS43: 835153 | BT43: 810426 | BU43: 778054 | BV43: 769312 | BW43: 772453 | BX43: 775350 | BY43: 768638 | BZ43: 774232 | CA43: 771525 | CB43: 775048 | CC43: 777940 | CD43: 750817 | CE43: 732779 | CF43: 723832 | CG43: 694105 | CH43: 658569 | CI43: 639590 | CJ43: 610038 | CK43: 565841 | CL43: 542693 | CM43: 524415 | CN43: 511820 | CO43: 501761 | CP43: 483512 | CQ43: 481434 | CR43: 497274 | CS43: 497959 | CT43: 508519 | CU43: 531457 | CV43: 536843 | CW43: 519131 | CX43: 513333 | CY43: 496598 | CZ43: 472963
A44: Medium | B44: Female | C44: '55-59 | D44: 186467 | E44: 187008 | F44: 190418 | G44: 193727 | H44: 197141 | I44: 205265 | J44: 219453 | K44: 230191 | L44: 240554 | M44: 251828 | N44: 263468 | O44: 271813 | P44: 280549 | Q44: 293298 | R44: 305711 | S44: 318463 | T44: 328412 | U44: 338390 | V44: 345160 | W44: 353725 | X44: 362900 | Y44: 369210 | Z44: 380987 | AA44: 388944 | AB44: 398378 | AC44: 409795 | AD44: 419368 | AE44: 424799 | AF44: 430770 | AG44: 429154 | AH44: 412352 | AI44: 403732 | AJ44: 414160 | AK44: 436233 | AL44: 475800 | AM44: 535893 | AN44: 614591 | AO44: 672051 | AP44: 720458 | AQ44: 760244 | AR44: 798855 | AS44: 817458 | AT44: 833060 | AU44: 853482 | AV44: 873221 | AW44: 885662 | AX44: 895613 | AY44: 914005 | AZ44: 927932 | BA44: 933118 | BB44: 932737 | BC44: 927991 | BD44: 913387 | BE44: 911937 | BF44: 909377 | BG44: 908211 | BH44: 900795 | BI44: 902441 | BJ44: 894170 | BK44: 886454 | BL44: 882508 | BM44: 909369 | BN44: 924960 | BO44: 950091 | BP44: 979521 | BQ44: 1002062 | BR44: 999760 | BS44: 1007721 | BT44: 995060 | BU44: 969720 | BV44: 934417 | BW44: 878227 | BX44: 828098 | BY44: 803761 | BZ44: 771840 | CA44: 763315 | CB44: 766507 | CC44: 769449 | CD44: 762889 | CE44: 768479 | CF44: 765848 | CG44: 769373 | CH44: 772269 | CI44: 745408 | CJ44: 727556 | CK44: 718727 | CL44: 689298 | CM44: 654111 | CN44: 635305 | CO44: 606026 | CP44: 562247 | CQ44: 539323 | CR44: 521227 | CS44: 508760 | CT44: 498806 | CU44: 480724 | CV44: 478683 | CW44: 494405 | CX44: 495099 | CY44: 505592 | CZ44: 528350
... A49: Medium | B49: Female | C49: '80-84 | D49: 28921 | E49: 19763 | F49: 20960 | G49: 21613 | H49: 22271 | I49: 23538 | J49: 24674 | K49: 26058 | L49: 28577 | M49: 30463 | N49: 32559 | O49: 35108 | P49: 37348 | Q49: 37844 | R49: 40248 | S49: 43751 | T49: 45814 | U49: 48891 | V49: 51579 | W49: 55072 | X49: 57792 | Y49: 62052 | Z49: 66767 | AA49: 71098 | AB49: 75905 | AC49: 78211 | AD49: 79052 | AE49: 81484 | AF49: 84458 | AG49: 87909 | AH49: 93801 | AI49: 102837 | AJ49: 110217 | AK49: 116899 | AL49: 124294 | AM49: 132174 | AN49: 140448 | AO49: 147906 | AP49: 157217 | AQ49: 166676 | AR49: 175596 | AS49: 183798 | AT49: 191268 | AU49: 198069 | AV49: 205840 | AW49: 213993 | AX49: 220018 | AY49: 229610 | AZ49: 238433 | BA49: 248977 | BB49: 259923 | BC49: 268252 | BD49: 272997 | BE49: 279753 | BF49: 281753 | BG49: 272212 | BH49: 269748 | BI49: 280842 | BJ49: 300634 | BK49: 332090 | BL49: 376456 | BM49: 433376 | BN49: 475354 | BO49: 510653 | BP49: 540069 | BQ49: 569098 | BR49: 584989 | BS49: 597958 | BT49: 614733 | BU49: 631659 | BV49: 643731 | BW49: 654199 | BX49: 670477 | BY49: 683852 | BZ49: 690386 | CA49: 694073 | CB49: 698264 | CC49: 689847 | CD49: 687025 | CE49: 687683 | CF49: 690087 | CG49: 687780 | CH49: 691339 | CI49: 687862 | CJ49: 684894 | CK49: 685096 | CL49: 710185 | CM49: 725141 | CN49: 747611 | CO49: 773326 | CP49: 793164 | CQ49: 794808 | CR49: 803403 | CS49: 795468 | CT49: 777585 | CU49: 751263 | CV49: 707895 | CW49: 669984 | CX49: 653567 | CY49: 630385 | CZ49: 626368
...

Sheet Dependency
B1: ='Population by 5-year age groups'!D10 -> 1970
A2: males
A3: 0-14 | B3: =SUM('Population by 5-year age groups'!D12:D14) -> 2994804
A4: 15-64 | B4: =SUM('Population by 5-year age groups'!D15:D24) -> 4544457
A5: 65+ | B5: =SUM('Population by 5-year age groups'!D25:D32) -> 193606
A6: females
A7: 0-14 | B7: =SUM('Population by 5-year age groups'!D33:D35) -> 2826335
A8: 15-64 | B8: =SUM('Population by 5-year age groups'!D36:D45) -> 3882033
A9: 65+ | B9: =SUM('Population by 5-year age groups'!D46:D53) -> 234729
A11: 0-14 | B11: =B3+B7 -> 5821139
A12: 15-64 | B12: =B4+B8 -> 8426490
A13: 65+ | B13: =B5+B9 -> 428335
A15: ratio <15 | B15: =B11/B12 -> 0.69081421
A16: ratio 65+ | B16: =B13/B12 -> 0.05083196
A17: both | B17: =SUM(B15:B16) -> 0.74164617

Sheet PPdata
B1: ='Population by 5-year age groups'!B11 -> Gender | C1: ='Population by 5-year age groups'!C11 -> Age | D1: 1970 | E1: 2012 | F1: 2054
A2: 0-4 | B2: ='Population by 5-year age groups'!B12 -> Male | C2: ='Population by 5-year age groups'!C12 -> '0-4 | D2: =-'Population by 5-year age groups'!D12 -> -974034 | E2: =-'Population by 5-year age groups'!AT12 -> -511559 | F2: =-'Population by 5-year age groups'!CJ12 -> -227354
A3: 5-9 | B3: ='Population by 5-year age groups'!B13 -> Male | C3: ='Population by 5-year age groups'!C13 -> '5-9 | D3: =-'Population by 5-year age groups'!D13 -> -1032745 | E3: =-'Population by 5-year age groups'!AT13 -> -558811 | F3: =-'Population by 5-year age groups'!CJ13 -> -259980
A4: 10-14 | B4: ='Population by 5-year age groups'!B14 -> Male | C4: ='Population by 5-year age groups'!C14 -> '10-14 | D4: =-'Population by 5-year age groups'!D14 -> -988025 | E4: =-'Population by 5-year age groups'!AT14 -> -709152 | F4: =-'Population by 5-year age groups'!CJ14 -> -274872
A5: 15-19 | B5: ='Population by 5-year age groups'!B15 -> Male | C5: ='Population by 5-year age groups'!C15 -> '15-19 | D5: =-'Population by 5-year age groups'!D15 -> -899138 | E5: =-'Population by 5-year age groups'!AT15 -> -839044 | F5: =-'Population by 5-year age groups'!CJ15 -> -292275
A6: 20-24 | B6: ='Population by 5-year age groups'!B16 -> Male | C6: ='Population by 5-year age groups'!C16 -> '20-24 | D6: =-'Population by 5-year age groups'!D16 -> -613923 | E6: =-'Population by 5-year age groups'!AT16 -> -840354 | F6: =-'Population by 5-year age groups'!CJ16 -> -309665
A7: 25-29 | B7: ='Population by 5-year age groups'!B17 -> Male | C7: ='Population by 5-year age groups'!C17 -> '25-29 | D7: =-'Population by 5-year age groups'!D17 -> -476385 | E7: =-'Population by 5-year age groups'!AT17 -> -857626 | F7: =-'Population by 5-year age groups'!CJ17 -> -338877
A8: 30-34 | B8: ='Population by 5-year age groups'!B18 -> Male | C8: ='Population by 5-year age groups'!C18 -> '30-34 | D8: =-'Population by 5-year age groups'!D18 -> -464656 | E8: =-'Population by 5-year age groups'!AT18 -> -1015792 | F8: =-'Population by 5-year age groups'!CJ18 -> -388969
A9: 35-39 | B9: ='Population by 5-year age groups'!B19 -> Male | C9: ='Population by 5-year age groups'!C19 -> '35-39 | D9: =-'Population by 5-year age groups'!D19 -> -457330 | E9: =-'Population by 5-year age groups'!AT19 -> -928490 | F9: =-'Population by 5-year age groups'!CJ19 -> -511831
A10: 40-44 | B10: ='Population by 5-year age groups'!B20 -> Male | C10: ='Population by 5-year age groups'!C20 -> '40-44 | D10: =-'Population by 5-year age groups'!D20 -> -510649 | E10: =-'Population by 5-year age groups'!AT20 -> -912991 | F10: =-'Population by 5-year age groups'!CJ20 -> -522705
A11: 45-49 | B11: ='Population by 5-year age groups'!B21 -> Male | C11: ='Population by 5-year age groups'!C21 -> '45-49 | D11: =-'Population by 5-year age groups'!D21 -> -419615 | E11: =-'Population by 5-year age groups'!AT21 -> -935207 | F11: =-'Population by 5-year age groups'!CJ21 -> -517339
A12: 50-54 | B12: ='Population by 5-year age groups'!B22 -> Male | C12: ='Population by 5-year age groups'!C22 -> '50-54 | D12: =-'Population by 5-year age groups'!D22 -> -300538 | E12: =-'Population by 5-year age groups'!AT22 -> -912094 | F12: =-'Population by 5-year age groups'!CJ22 -> -625719
A13: 55-59 | B13: ='Population by 5-year age groups'!B23 -> Male | C13: ='Population by 5-year age groups'!C23 -> '55-59 | D13: =-'Population by 5-year age groups'!D23 -> -244831 | E13: =-'Population by 5-year age groups'!AT23 -> -803377 | F13: =-'Population by 5-year age groups'!CJ23 -> -731424
... A18: 80-84 | B18: ='Population by 5-year age groups'!B28 -> Male | C18: ='Population by 5-year age groups'!C28 -> '80-84 | D18: =-'Population by 5-year age groups'!D28 -> -13883 | E18: =-'Population by 5-year age groups'!AT28 -> -187308 | F18: =-'Population by 5-year age groups'!CJ28 -> -479413
A19: 85-89 | B19: ='Population by 5-year age groups'!B29 -> Male | C19: ='Population by 5-year age groups'!C29 -> '85-89 | E19: =-'Population by 5-year age groups'!AT29 -> -98577 | F19: =-'Population by 5-year age groups'!CJ29 -> -345867
A20: 90-94 | B20: ='Population by 5-year age groups'!B30 -> Male | C20: ='Population by 5-year age groups'!C30 -> '90-94 | E20: =-'Population by 5-year age groups'!AT30 -> -30022 | F20: =-'Population by 5-year age groups'!CJ30 -> -193949
A21: 95-99 | B21: ='Population by 5-year age groups'!B31 -> Male | C21: ='Population by 5-year age groups'!C31 -> '95-99 | E21: =-'Population by 5-year age groups'!AT31 -> -5752 | F21: =-'Population by 5-year age groups'!CJ31 -> -66773
A22: 100 + | B22: ='Population by 5-year age groups'!B32 -> Male | C22: ='Population by 5-year age groups'!C32 -> '100 + | E22: =-'Population by 5-year age groups'!AT32 -> -1315 | F22: =-'Population by 5-year age groups'!CJ32 -> -11775
B23: ='Population by 5-year age groups'!B33 -> Female | C23: ='Population by 5-year age groups'!C33 -> '0-4 | D23: ='Population by 5-year age groups'!D33 -> 914496 | E23: ='Population by 5-year age groups'!AT33 -> 472124 | F23: ='Population by 5-year age groups'!CJ33 -> 202679
B24: ='Population by 5-year age groups'!B34 -> Female | C24: ='Population by 5-year age groups'!C34 -> '5-9 | D24: ='Population by 5-year age groups'!D34 -> 974686 | E24: ='Population by 5-year age groups'!AT34 -> 509463 | F24: ='Population by 5-year age groups'!CJ34 -> 230896
B25: ='Population by 5-year age groups'!B35 -> Female | C25: ='Population by 5-year age groups'!C35 -> '10-14 | D25: ='Population by 5-year age groups'!D35 -> 937153 | E25: ='Population by 5-year age groups'!AT35 -> 650568 | F25: ='Population by 5-year age groups'!CJ35 -> 245519
B26: ='Population by 5-year age groups'!B36 -> Female | C26: ='Population by 5-year age groups'!C36 -> '15-19 | D26: ='Population by 5-year age groups'!D36 -> 854662 | E26: ='Population by 5-year age groups'!AT36 -> 776481 | F26: ='Population by 5-year age groups'!CJ36 -> 263398
B27: ='Population by 5-year age groups'!B37 -> Female | C27: ='Population by 5-year age groups'!C37 -> '20-24 | D27: ='Population by 5-year age groups'!D37 -> 584014 | E27: ='Population by 5-year age groups'!AT37 -> 775225 | F27: ='Population by 5-year age groups'!CJ37 -> 283680
B28: ='Population by 5-year age groups'!B38 -> Female | C28: ='Population by 5-year age groups'!C38 -> '25-29 | D28: ='Population by 5-year age groups'!D38 -> 449632 | E28: ='Population by 5-year age groups'!AT38 -> 830809 | F28: ='Population by 5-year age groups'!CJ38 -> 315864
B29: ='Population by 5-year age groups'!B39 -> Female | C29: ='Population by 5-year age groups'!C39 -> '30-34 | D29: ='Population by 5-year age groups'!D39 -> 443492 | E29: ='Population by 5-year age groups'!AT39 -> 1023196 | F29: ='Population by 5-year age groups'!CJ39 -> 372354
B30: ='Population by 5-year age groups'!B40 -> Female | C30: ='Population by 5-year age groups'!C40 -> '35-39 | D30: ='Population by 5-year age groups'!D40 -> 388501 | E30: ='Population by 5-year age groups'!AT40 -> 945898 | F30: ='Population by 5-year age groups'!CJ40 -> 494761
B31: ='Population by 5-year age groups'!B41 -> Female | C31: ='Population by 5-year age groups'!C41 -> '40-44 | D31: ='Population by 5-year age groups'!D41 -> 339713 | E31: ='Population by 5-year age groups'!AT41 -> 924215 | F31: ='Population by 5-year age groups'!CJ41 -> 509814
B32: ='Population by 5-year age groups'!B42 -> Female | C32: ='Population by 5-year age groups'!C42 -> '45-49 | D32: ='Population by 5-year age groups'!D42 -> 278713 | E32: ='Population by 5-year age groups'!AT42 -> 939746 | F32: ='Population by 5-year age groups'!CJ42 -> 503231
B33: ='Population by 5-year age groups'!B43 -> Female | C33: ='Population by 5-year age groups'!C43 -> '50-54 | D33: ='Population by 5-year age groups'!D43 -> 213902 | E33: ='Population by 5-year age groups'!AT43 -> 926068 | F33: ='Population by 5-year age groups'!CJ43 -> 610038
B34: ='Population by 5-year age groups'!B44 -> Female | C34: ='Population by 5-year age groups'!C44 -> '55-59 | D34: ='Population by 5-year age groups'!D44 -> 186467 | E34: ='Population by 5-year age groups'!AT44 -> 833060 | F34: ='Population by 5-year age groups'!CJ44 -> 727556
... B39: ='Population by 5-year age groups'!B49 -> Female | C39: ='Population by 5-year age groups'!C49 -> '80-84 | D39: ='Population by 5-year age groups'!D49 -> 28921 | E39: ='Population by 5-year age groups'!AT49 -> 191268 | F39: ='Population by 5-year age groups'!CJ49 -> 684894
B40: ='Population by 5-year age groups'!B50 -> Female | C40: ='Population by 5-year age groups'!C50 -> '85-89 | E40: ='Population by 5-year age groups'!AT50 -> 100306 | F40: ='Population by 5-year age groups'!CJ50 -> 554961
B41: ='Population by 5-year age groups'!B51 -> Female | C41: ='Population by 5-year age groups'!C51 -> '90-94 | E41: ='Population by 5-year age groups'!AT51 -> 36268 | F41: ='Population by 5-year age groups'!CJ51 -> 370655
B42: ='Population by 5-year age groups'!B52 -> Female | C42: ='Population by 5-year age groups'!C52 -> '95-99 | E42: ='Population by 5-year age groups'!AT52 -> 7833 | F42: ='Population by 5-year age groups'!CJ52 -> 160897
